Workbook

Sheet 摘要
A1: 航宇科技（688239.SH）— 财务研究模型
A2: 数据来源：iFind/研究报告/分析师预测 | 单位：亿元人民币 | 截至：2026-04-07
A4: ▌ 公司概况
A5: 股票代码 | B5: 688239.SH
A6: 行业 | B6: 国防军工/航空锻造
A7: 主营业务 | B7: 航空难变形金属材料环形锻件
A8: 总股本 | B8: 1.90亿股
A9: 当前股价 | B9: 54.14元
A10: 总市值 | B10: 103亿元
A12: ▌ 历史财务概要
A13: 指标 | B13: 2020A | C13: 2021A | D13: 2022A | E13: 2023A | F13: 2024A | G13: 2025A
A14: 营业收入 | B14: =利润表!B4 | C14: =利润表!C4 | D14: =利润表!D4 | E14: =利润表!E4 | F14: =利润表!F4 | G14: =利润表!G4
A15: YoY增速 | B15: =利润表!B5 | C15: =利润表!C5 | D15: =利润表!D5 | E15: =利润表!E5 | F15: =利润表!F5 | G15: =利润表!G5
A16: 毛利润 | B16: =利润表!B7 | C16: =利润表!C7 | D16: =利润表!D7 | E16: =利润表!E7 | F16: =利润表!F7 | G16: =利润表!G7
A17: 毛利率 | B17: =利润表!B8 | C17: =利润表!C8 | D17: =利润表!D8 | E17: =利润表!E8 | F17: =利润表!F8 | G17: =利润表!G8
A18: 归母净利润 | B18: =利润表!B22 | C18: =利润表!C22 | D18: =利润表!D22 | E18: =利润表!E22 | F18: =利润表!F22 | G18: =利润表!G22
A19: 归母净利率 | B19: =利润表!B24 | C19: =利润表!C24 | D19: =利润表!D24 | E19: =利润表!E24 | F19: =利润表!F24 | G19: =利润表!G24
A20: EPS（元） | B20: =利润表!B25 | C20: =利润表!C25 | D20: =利润表!D25 | E20: =利润表!E25 | F20: =利润表!F25 | G20: =利润表!G25
A22: ▌ 预测摘要（2026E-2030E）
A23: 指标 | B23: 2026E | C23: 2027E | D23: 2028E | E23: 2029E | F23: 2030E
A24: 营业收入 | B24: =利润表!H4 | C24: =利润表!I4 | D24: =利润表!J4 | E24: =利润表!K4 | F24: =利润表!L4
A25: YoY增速 | B25: =利润表!H5 | C25: =利润表!I5 | D25: =利润表!J5 | E25: =利润表!K5 | F25: =利润表!L5
A26: 归母净利润 | B26: =利润表!H22 | C26: =利润表!I22 | D26: =利润表!J22 | E26: =利润表!K22 | F26: =利润表!L22
A27: 归母净利YoY | B27: =利润表!H23 | C27: =利润表!I23 | D27: =利润表!J23 | E27: =利润表!K23 | F27: =利润表!L23
A28: EPS（元） | B28: =利润表!H25 | C28: =利润表!I25 | D28: =利润表!J25 | E28: =利润表!K25 | F28: =利润表!L25
A29: PE（x） | B29: - | C29: - | D29: - | E29: - | F29: -
A31: ▌ 质量评分
A32: 综合质量得分 | B32: =基本面研究!D11
A33: 投资等级 | B33: B档（良好）
A35: ▌ 估值结论
A36: 当前PE（TTM） | B36: 55.2x
A37: 目标价区间 | B37: 64-72元
A38: 上行空间 | B38: +18%~+33%
A39: 投资评级 | B39: 中性偏乐观

Sheet 业务拆分
A1: 【业务拆分】航宇科技（688239.SH）— 分部收入与毛利率预测
A2: 单位：亿元人民币 | 蓝色=手动输入假设 | 黑色=公式计算 | B2: 2020A | C2: 2021A | D2: 2022A | E2: 2023A | F2: 2024A | G2: 2025A | H2: 2026E | I2: 2027E | J2: 2028E | K2: 2029E | L2: 2030E
A3: 航空锻件（国内） 收入 | B3: 0 | C3: 0 | D3: 5.82 | E3: 8.42 | F3: 7.22 | G3: 8.14 | H3: =G3*(1+H4) | I3: =H3*(1+I4) | J3: =I3*(1+J4) | K3: =J3*(1+K4) | L3: =K3*(1+L4)
A4: 航空锻件（国内） 增速 | E4: =(E3-D3)/D3 | F4: =(F3-E3)/E3 | G4: =(G3-F3)/F3 | H4: 0.08 | I4: 0.12 | J4: 0.15 | K4: 0.12 | L4: 0.1
A5: 航空锻件（国内） 毛利率 | B5: 0 | C5: 0 | D5: 0.28 | E5: 0.272 | F5: 0.275 | G5: 0.278 | H5: 0.28 | I5: 0.282 | J5: 0.285 | K5: 0.285 | L5: 0.285
A6: 航空锻件（国内） 毛利额 | B6: =B3*B5 | C6: =C3*C5 | D6: =D3*D5 | E6: =E3*E5 | F6: =F3*F5 | G6: =G3*G5 | H6: =H3*H5 | I6: =I3*I5 | ... L6: =L3*L5
A7: 航空锻件（海外） 收入 | B7: 0 | C7: 0 | D7: 5.45 | E7: 8.12 | F7: 7.22 | G7: 9.11 | H7: =G7*(1+H8) | I7: =H7*(1+I8) | J7: =I7*(1+J8) | K7: =J7*(1+K8) | L7: =K7*(1+L8)
A8: 航空锻件（海外） 增速 | E8: =(E7-D7)/D7 | F8: =(F7-E7)/E7 | G8: =(G7-F7)/F7 | H8: 0.18 | I8: 0.2 | J8: 0.18 | K8: 0.15 | L8: 0.12
A9: 航空锻件（海外） 毛利率 | B9: 0 | C9: 0 | D9: 0.305 | E9: 0.295 | F9: 0.298 | G9: 0.302 | H9: 0.305 | I9: 0.308 | J9: 0.31 | K9: 0.31 | L9: 0.31
A10: 航空锻件（海外） 毛利额 | B10: =B7*B9 | C10: =C7*C9 | D10: =D7*D9 | E10: =E7*E9 | F10: =F7*F9 | G10: =G7*G9 | H10: =H7*H9 | I10: =I7*I9 | ... L10: =L7*L9
A11: 燃气轮机锻件 收入 | B11: 0 | C11: 0 | D11: 2.18 | E11: 3.15 | F11: 2.71 | G11: 3.05 | H11: =G11*(1+H12) | I11: =H11*(1+I12) | J11: =I11*(1+J12) | K11: =J11*(1+K12) | L11: =K11*(1+L12)
A12: 燃气轮机锻件 增速 | E12: =(E11-D11)/D11 | F12: =(F11-E11)/E11 | G12: =(G11-F11)/F11 | H12: 0.5 | I12: 0.45 | J12: 0.35 | K12: 0.25 | L12: 0.2
A13: 燃气轮机锻件 毛利率 | B13: 0 | C13: 0 | D13: 0.28 | E13: 0.268 | F13: 0.275 | G13: 0.295 | H13: 0.3 | I13: 0.305 | J13: 0.308 | K13: 0.308 | L13: 0.308
A14: 燃气轮机锻件 毛利额 | B14: =B11*B13 | C14: =C11*C13 | D14: =D11*D13 | E14: =E11*E13 | F14: =F11*F13 | G14: =G11*G13 | H14: =H11*H13 | I14: =I11*I13 | ... L14: =L11*L13
A15: 航天锻件 收入 | B15: 0 | C15: 0 | D15: 1.1 | E15: 1.35 | F15: 0.9 | G15: 0.85 | H15: =G15*(1+H16) | I15: =H15*(1+I16) | J15: =I15*(1+J16) | K15: =J15*(1+K16) | L15: =K15*(1+L16)
A16: 航天锻件 增速 | E16: =(E15-D15)/D15 | F16: =(F15-E15)/E15 | G16: =(G15-F15)/F15 | H16: 0.2 | I16: 0.25 | J16: 0.25 | K16: 0.2 | L16: 0.15
A17: 航天锻件 毛利率 | B17: 0 | C17: 0 | D17: 0.18 | E17: 0.165 | F17: 0.168 | G17: 0.17 | H17: 0.175 | I17: 0.178 | J17: 0.18 | K17: 0.18 | L17: 0.18
A18: 航天锻件 毛利额 | B18: =B15*B17 | C18: =C15*C17 | D18: =D15*D17 | E18: =E15*E17 | F18: =F15*F17 | G18: =G15*G17 | H18: =H15*H17 | I18: =I15*I17 | ... L18: =L15*L17
A19: 汇总：总收入 | B19: =B3+B7+B11+B15 | C19: =C3+C7+C11+C15 | D19: =D3+D7+D11+D15 | E19: =E3+E7+E11+E15 | F19: =F3+F7+F11+F15 | G19: =G3+G7+G11+G15 | H19: =H3+H7+H11+H15 | I19: =I3+I7+I11+I15 | ... L19: =L3+L7+L11+L15
A20: 汇总：总毛利额 | B20: =B6+B10+B14+B18 | C20: =C6+C10+C14+C18 | D20: =D6+D10+D14+D18 | E20: =E6+E10+E14+E18 | F20: =F6+F10+F14+F18 | G20: =G6+G10+G14+G18 | H20: =H6+H10+H14+H18 | I20: =I6+I10+I14+I18 | ... L20: =L6+L10+L14+L18
A21: 综合毛利率 | B21: =B20/B19 | C21: =C20/C19 | D21: =D20/D19 | E21: =E20/E19 | F21: =F20/F19 | G21: =G20/G19 | H21: =H20/H19 | I21: =I20/I19 | ... L21: =L20/L19
A22: 营收增速 | C22: =(C19-B19)/B19 | D22: =(D19-C19)/C19 | E22: =(E19-D19)/D19 | F22: =(F19-E19)/E19 | G22: =(G19-F19)/F19 | H22: =(H19-G19)/G19 | I22: =(I19-H19)/H19 | J22: =(J19-I19)/I19 | ... L22: =(L19-K19)/K19

Sheet 模型假设
A1: 【模型假设】航宇科技（688239.SH）— 可调参数控制中心
A2: 说明：蓝色=手动输入，绿色=业务拆分引用，黑色=公式计算
A3: 假设项目 | B3: 2026E | C3: 2027E | D3: 2028E | E3: 2029E | F3: 2030E | G3: 来源：iFind/研究报告/分析师预测
A4: ▌ A. 收入假设
A5: 营收增速 | B5: =业务拆分!H22 | C5: =业务拆分!I22 | D5: =业务拆分!J22 | E5: =业务拆分!K22 | F5: =业务拆分!L22
A6: ▌ B. 盈利能力
A7: 综合毛利率 | B7: =业务拆分!H21 | C7: =业务拆分!I21 | D7: =业务拆分!J21 | E7: =业务拆分!K21 | F7: =业务拆分!L21
A8: 销售费用率 | B8: 0.025 | C8: 0.024 | D8: 0.023 | E8: 0.022 | F8: 0.022
A9: 管理费用率 | B9: 0.065 | C9: 0.063 | D9: 0.06 | E9: 0.058 | F9: 0.055
A10: 研发费用率 | B10: 0.062 | C10: 0.06 | D10: 0.058 | E10: 0.055 | F10: 0.052
A11: 净财务收入（亿） | B11: -0.08 | C11: -0.1 | D11: -0.12 | E11: -0.12 | F11: -0.1
A12: 有效税率 | B12: 0.135 | C12: 0.13 | D12: 0.128 | E12: 0.125 | F12: 0.125
A13: 归母/合并净利润比例 | B13: 0.92 | C13: 0.93 | D13: 0.93 | E13: 0.93 | F13: 0.93
A14: ▌ C. 资本开支 & 折旧摊销
A15: D&A 折旧摊销（亿） | B15: 1.85 | C15: 2.05 | D15: 2.25 | E15: 2.45 | F15: 2.65
A16: 资本开支 Capex（亿） | B16: 4.8 | C16: 5.2 | D16: 5.5 | E16: 5.8 | F16: 6
A17: ▌ D. 营运资本
A18: 应收账款天数 | B18: 145 | C18: 140 | D18: 135 | E18: 130 | F18: 128
A19: 存货周转天数 | B19: 155 | C19: 150 | D19: 148 | E19: 145 | F19: 142
A20: 应付账款天数 | B20: 145 | C20: 142 | D20: 140 | E20: 138 | F20: 135
A21: ▌ E. 资本结构
A22: 股息支付率 | B22: 0.15 | C22: 0.15 | D22: 0.15 | E22: 0.18 | F22: 0.2
A23: ▌ F. 估值参数
A24: WACC (%) | B24: 0.085 | C24: 0.085 | D24: 0.085 | E24: 0.085 | F24: 0.085
A26: 总股本（亿股） | B26: 1.9 | C26: 1.9 | D26: 1.9 | E26: 1.9 | F26: 1.9
A27: 当前股价（元） | B27: 54.14 | C27: 54.14 | D27: 54.14 | E27: 54.14 | F27: 54.14

Sheet 利润表
A1: 【利润表】航宇科技（688239.SH）
A2: 单位：亿元人民币
A3: 科目 | B3: 2020A | C3: 2021A | D3: 2022A | E3: 2023A | F3: 2024A | G3: 2025A | H3: 2026E | I3: 2027E | J3: 2028E | K3: 2029E | L3: 2030E
A4: 营业收入 | B4: 12.13 | C4: 14.29 | D4: 14.55 | E4: 21.04 | F4: 18.05 | G4: 20.34 | H4: =G4*(1+模型假设!$B$5) | I4: =H4*(1+模型假设!$C$5) | J4: =I4*(1+模型假设!$D$5) | K4: =J4*(1+模型假设!$E$5) | L4: =K4*(1+模型假设!$F$5)
A5: YoY增速 | C5: =(C4-B4)/B4 | D5: =(D4-C4)/C4 | E5: =(E4-D4)/D4 | F5: =(F4-E4)/E4 | G5: =(G4-F4)/F4 | H5: =(H4-G4)/G4 | I5: =(I4-H4)/H4 | J5: =(J4-I4)/I4 | ... L5: =(L4-K4)/K4
A6: 营业成本 | B6: -8.65 | C6: -10.1 | D6: -10.28 | E6: -15.12 | F6: -12.98 | G6: -14.65 | H6: =-(H4-H7) | I6: =-(I4-I7) | J6: =-(J4-J7) | K6: =-(K4-K7) | L6: =-(L4-L7)
A7: 毛利润 | B7: 3.48 | C7: 4.19 | D7: 4.27 | E7: 5.92 | F7: 5.07 | G7: 5.69 | H7: =H4*模型假设!$B$7 | I7: =I4*模型假设!$C$7 | J7: =J4*模型假设!$D$7 | K7: =K4*模型假设!$E$7 | L7: =L4*模型假设!$F$7
A8: 毛利率 | B8: 0.287 | C8: 0.293 | D8: 0.294 | E8: 0.281 | F8: 0.28 | G8: 0.28
A9: 期间费用
A10: 销售费用 | B10: -0.36 | C10: -0.42 | D10: -0.44 | E10: -0.52 | F10: -0.48 | G10: -0.52 | H10: =-H4*模型假设!$B$8 | I10: =-I4*模型假设!$C$8 | J10: =-J4*模型假设!$D$8 | K10: =-K4*模型假设!$E$8 | L10: =-L4*模型假设!$F$8
A11: 管理费用 | B11: -0.87 | C11: -1.01 | D11: -1.08 | E11: -1.35 | F11: -1.25 | G11: -1.32 | H11: =-H4*模型假设!$B$9 | I11: =-I4*模型假设!$C$9 | J11: =-J4*模型假设!$D$9 | K11: =-K4*模型假设!$E$9 | L11: =-L4*模型假设!$F$9
A12: 研发费用 | B12: -0.62 | C12: -0.75 | D12: -0.82 | E12: -1.15 | F12: -1.08 | G12: -1.25 | H12: =-H4*模型假设!$B$10 | I12: =-I4*模型假设!$C$10 | J12: =-J4*模型假设!$D$10 | K12: =-K4*模型假设!$E$10 | L12: =-L4*模型假设!$F$10
A13: 研发费用率 | B13: 0.051112943 | C13: 0.052484255 | D13: 0.056357388 | E13: 0.054657795 | F13: 0.059833795 | G13: 0.061455261 | H13: =-H12/H4 | I13: =-I12/I4 | J13: =-J12/J4 | K13: =-K12/K4 | L13: =-L12/L4
A14: 财务费用（净额） | B14: -0.18 | C14: -0.12 | D14: -0.08 | E14: -0.05 | F14: -0.02 | G14: 0.05 | H14: =-模型假设!$B$11 | I14: =-模型假设!$C$11 | J14: =-模型假设!$D$11 | K14: =-模型假设!$E$11 | L14: =-模型假设!$F$11
A16: 营业利润 | B16: 2.16 | C16: 2.68 | D16: 2.75 | E16: 4.12 | F16: 3.52 | G16: 3.85 | H16: =H7+H10+H11+H12+H14 | I16: =I7+I10+I11+I12+I14 | J16: =J7+J10+J11+J12+J14 | K16: =K7+K10+K11+K12+K14 | L16: =L7+L10+L11+L12+L14
A17: 营业利润率 | B17: 0.1780709 | C17: 0.18754374 | D17: 0.18900344 | E17: 0.19581749 | F17: 0.19501385 | G17: 0.1892822 | H17: =H16/H4 | I17: =I16/I4 | J17: =J16/J4 | K17: =K16/K4 | L17: =L16/L4
A18: EBITDA | B18: 3.373 | C18: 4.109 | D18: 4.205 | E18: 6.224 | F18: 5.325 | G18: 5.884 | H18: =H16+模型假设!$B$15 | I18: =I16+模型假设!$C$15 | J18: =J16+模型假设!$D$15 | K18: =K16+模型假设!$E$15 | L18: =L16+模型假设!$F$15
A19: EBITDA率 | B19: 0.2780709 | C19: 0.28754374 | D19: 0.28900344 | E19: 0.29581749 | F19: 0.29501385 | G19: 0.2892822 | H19: =H18/H4 | I19: =I18/I4 | J19: =J18/J4 | K19: =K18/K4 | L19: =L18/L4
A21: 净利润（合并） | B21: 1.65 | C21: 2.05 | D21: 2.21 | E21: 3.28 | F21: 2.68 | G21: 2.92 | H21: =H16*(1-模型假设!$B$12) | I21: =I16*(1-模型假设!$C$12) | J21: =J16*(1-模型假设!$D$12) | K21: =K16*(1-模型假设!$E$12) | L21: =L16*(1-模型假设!$F$12)
A22: 归母净利润 | B22: 1.65 | C22: 2.05 | D22: 1.84 | E22: 1.86 | F22: 1.89 | G22: 1.86 | H22: =H21*模型假设!$B$13 | I22: =I21*模型假设!$C$13 | J22: =J21*模型假设!$D$13 | K22: =K21*模型假设!$E$13 | L22: =L21*模型假设!$F$13
A23: 归母净利YoY | C23: =(C22-B22)/B22 | D23: =(D22-C22)/C22 | E23: =(E22-D22)/D22 | F23: =(F22-E22)/E22 | G23: =(G22-F22)/F22 | H23: =(H22-G22)/G22 | I23: =(I22-H22)/H22 | J23: =(J22-I22)/I22 | ... L23: =(L22-K22)/K22
A24: 归母净利率 | B24: 0.13602638 | C24: 0.14345696 | D24: 0.12646048 | E24: 0.088403042 | F24: 0.10470914 | G24: 0.091445428 | H24: =H22/H4 | I24: =I22/I4 | J24: =J22/J4 | K24: =K22/K4 | L24: =L22/L4
A25: EPS（元/股） | B25: 1.15 | C25: 1.42 | D25: 1.27 | E25: 1.28 | F25: 1.3 | G25: 0.98 | H25: =H22/模型假设!$B$26 | I25: =I22/模型假设!$B$26 | J25: =J22/模型假设!$B$26 | K25: =K22/模型假设!$B$26 | L25: =L22/模型假设!$B$26

Sheet 资产负债表
A1: 【资产负债表】航宇科技（688239.SH）
A2: 单位：亿元人民币
A3: 科目 | B3: 2020A | C3: 2021A | D3: 2022A | E3: 2023A | F3: 2024A | G3: 2025A | H3: 2026E | I3: 2027E | J3: 2028E | K3: 2029E | L3: 2030E
A4: 流动资产
A5: 货币资金 | B5: 5.82 | C5: 7.45 | D5: 8.92 | E5: 9.85 | F5: 10.52 | G5: 12.15 | H5: =现金流量表!H13 | I5: =现金流量表!I13 | J5: =现金流量表!J13 | K5: =现金流量表!K13 | L5: =现金流量表!L13
A6: 应收账款 | B6: 3.45 | C6: 4.12 | D6: 4.56 | E6: 5.82 | F6: 6.98 | G6: 8.25 | H6: =利润表!H4*模型假设!$B$18/365 | I6: =利润表!I4*模型假设!$C$18/365 | J6: =利润表!J4*模型假设!$D$18/365 | K6: =利润表!K4*模型假设!$E$18/365 | L6: =利润表!L4*模型假设!$F$18/365
A7: 存货 | B7: 2.31 | C7: 2.78 | D7: 3.12 | E7: 4.25 | F7: 5.12 | G7: 6.15 | H7: =-利润表!H6*模型假设!$B$19/365 | I7: =-利润表!I6*模型假设!$C$19/365 | J7: =-利润表!J6*模型假设!$D$19/365 | K7: =-利润表!K6*模型假设!$E$19/365 | L7: =-利润表!L6*模型假设!$F$19/365
A8: 其他流动资产 | B8: 1.2 | C8: 1.55 | D8: 1.82 | E8: 2.15 | F8: 2.45 | G8: 2.85 | H8: =G8*0.99 | I8: =H8*0.99 | J8: =I8*0.99 | K8: =J8*0.99 | L8: =K8*0.99
A9: 流动资产合计 | B9: 12.78 | C9: 15.9 | D9: 18.42 | E9: 22.07 | F9: 25.07 | G9: 29.4 | H9: =SUM(H5:H8) | I9: =SUM(I5:I8) | J9: =SUM(J5:J8) | K9: =SUM(K5:K8) | L9: =SUM(L5:L8)
A10: 非流动资产
A11: 固定资产+在建工程 | B11: 6.54 | C11: 7.82 | D11: 9.15 | E11: 10.58 | F11: 12.15 | G11: 13.85 | H11: =G11+模型假设!$B$16-模型假设!$B$15 | I11: =H11+模型假设!$C$16-模型假设!$C$15 | J11: =I11+模型假设!$D$16-模型假设!$D$15 | K11: =J11+模型假设!$E$16-模型假设!$E$15 | L11: =K11+模型假设!$F$16-模型假设!$F$15
A12: 其他非流动资产 | B12: 3.21 | C12: 3.85 | D12: 4.2 | E12: 4.92 | F12: 5.45 | G12: 6.12 | H12: =G12*1.01 | I12: =H12*1.01 | J12: =I12*1.01 | K12: =J12*1.01 | L12: =K12*1.01
A13: 非流动资产合计 | B13: 9.75 | C13: 11.67 | D13: 13.35 | E13: 15.5 | F13: 17.6 | G13: 19.97 | H13: =H11+H12 | I13: =I11+I12 | J13: =J11+J12 | K13: =K11+K12 | L13: =L11+L12
A14: 资产总计 | B14: 22.53 | C14: 27.57 | D14: 31.77 | E14: 37.57 | F14: 42.67 | G14: 49.37 | H14: =H9+H13 | I14: =I9+I13 | J14: =J9+J13 | K14: =K9+K13 | L14: =L9+L13
A15: 流动负债
A17: 短期借款 | B17: 2.1 | C17: 2.35 | D17: 2.55 | E17: 2.85 | F17: 3.12 | G17: 3.45 | H17: =G17 | I17: =H17 | J17: =I17 | K17: =J17 | L17: =K17
A18: 应付账款 | B18: 2.85 | C18: 3.42 | D18: 3.78 | E18: 4.52 | F18: 5.15 | G18: 5.85 | H18: =-利润表!H6*模型假设!$B$20/365 | I18: =-利润表!I6*模型假设!$C$20/365 | J18: =-利润表!J6*模型假设!$D$20/365 | K18: =-利润表!K6*模型假设!$E$20/365 | L18: =-利润表!L6*模型假设!$F$20/365
A19: 其他流动负债 | B19: 1.45 | C19: 1.78 | D19: 2.05 | E19: 2.45 | F19: 2.85 | G19: 3.15 | H19: =G19*0.98 | I19: =H19*0.98 | J19: =I19*0.98 | K19: =J19*0.98 | L19: =K19*0.98
A20: 流动负债合计 | B20: 6.4 | C20: 7.55 | D20: 8.38 | E20: 9.82 | F20: 11.12 | G20: 12.45 | H20: =H17+H18+H19 | I20: =I17+I18+I19 | J20: =J17+J18+J19 | K20: =K17+K18+K19 | L20: =L17+L18+L19
A21: 非流动负债
A22: 长期借款 | B22: 0.85 | C22: 0.95 | D22: 1.05 | E22: 1.25 | F22: 1.45 | G22: 1.65 | H22: =G22 | I22: =H22 | J22: =I22 | K22: =J22 | L22: =K22
A23: 其他非流动负债 | B23: 0.62 | C23: 0.78 | D23: 0.85 | E23: 0.95 | F23: 1.08 | G23: 1.25 | H23: =G23*1.02 | I23: =H23*1.02 | J23: =I23*1.02 | K23: =J23*1.02 | L23: =K23*1.02
A24: 非流动负债合计 | B24: 1.47 | C24: 1.73 | D24: 1.9 | E24: 2.2 | F24: 2.53 | G24: 2.9 | H24: =H22+H23 | I24: =I22+I23 | J24: =J22+J23 | K24: =K22+K23 | L24: =L22+L23
A25: 负债合计 | B25: 7.87 | C25: 9.28 | D25: 10.28 | E25: 12.02 | F25: 13.65 | G25: 15.35 | H25: =H20+H24 | I25: =I20+I24 | J25: =J20+J24 | K25: =K20+K24 | L25: =L20+L24
A26: 股东权益
A28: 归母股东权益 | B28: 9.86 | C28: 11.52 | D28: 13.15 | E28: 15.25 | F28: 16.85 | G28: 18.52 | H28: =G28+利润表!H22*(1-模型假设!$B$22) | I28: =H28+利润表!I22*(1-模型假设!$C$22) | J28: =I28+利润表!J22*(1-模型假设!$D$22) | K28: =J28+利润表!K22*(1-模型假设!$E$22) | L28: =K28+利润表!L22*(1-模型假设!$F$22)
A29: 少数股东权益 | B29: 0.35 | C29: 0.42 | D29: 0.51 | E29: 0.58 | F29: 0.65 | G29: 0.72 | H29: =G29*1.02 | I29: =H29*1.02 | J29: =I29*1.02 | K29: =J29*1.02 | L29: =K29*1.02
A30: 股东权益合计 | B30: 10.21 | C30: 11.94 | D30: 13.66 | E30: 15.83 | F30: 17.5 | G30: 19.24 | H30: =H28+H29 | I30: =I28+I29 | J30: =J28+J29 | K30: =K28+K29 | L30: =L28+L29
A31: 验证（负债+权益） | B31: 18.08 | C31: 21.22 | D31: 23.94 | E31: 27.85 | F31: 31.15 | G31: 34.59 | H31: =H25+H30 | I31: =I25+I30 | J31: =J25+J30 | K31: =K25+K30 | L31: =L25+L30
A33: 资产负债率 | B33: 0.34931203 | C33: 0.33659775 | D33: 0.3235757 | E33: 0.31993612 | F33: 0.31989688 | G33: 0.31091756 | H33: =H25/H14 | I33: =I25/I14 | J33: =J25/J14 | K33: =K25/K14 | L33: =L25/L14
A34: 净负债/权益 | B34: -0.28109696 | C34: -0.34757119 | D34: -0.38945827 | E34: -0.36323437 | F34: -0.34 | G34: -0.36642412 | H34: =(H17+H22-H5)/H30 | I34: =(I17+I22-I5)/I30 | J34: =(J17+J22-J5)/J30 | K34: =(K17+K22-K5)/K30 | L34: =(L17+L22-L5)/L30

Sheet 现金流量表
A1: 【现金流量表】航宇科技（688239.SH）
A2: 单位：亿元人民币
A3: 科目 | B3: 2020A | C3: 2021A | D3: 2022A | E3: 2023A | F3: 2024A | G3: 2025A | H3: 2026E | I3: 2027E | J3: 2028E | K3: 2029E | L3: 2030E
A4: 经营活动现金流 | B4: 1.82 | C4: 2.15 | D4: 2.45 | E4: 2.85 | F4: 1.44 | G4: 2.15 | H4: =利润表!H21+模型假设!$B$15-((资产负债表!H6-资产负债表!G6)+(资产负债表!H7-资产负债表!G7)-(资产负债表!H18-资产负债表!G18)) | I4: =利润表!I21+模型假设!$C$15-((资产负债表!I6-资产负债表!H6)+(资产负债表!I7-资产负债表!H7)-(资产负债表!I18-资产负债表!H18)) | J4: =利润表!J21+模型假设!$D$15-((资产负债表!J6-资产负债表!I6)+(资产负债表!J7-资产负债表!I7)-(资产负债表!J18-资产负债表!I18)) | K4: =利润表!K21+模型假设!$E$15-((资产负债表!K6-资产负债表!J6)+(资产负债表!K7-资产负债表!J7)-(资产负债表!K18-资产负债表!J18)) | L4: =利润表!L21+模型假设!$F$15-((资产负债表!L6-资产负债表!K6)+(资产负债表!L7-资产负债表!K7)-(资产负债表!L18-资产负债表!K18))
A5: 资本开支（Capex） | B5: 1.95 | C5: 2.45 | D5: 2.8 | E5: 3.2 | F5: 3.85 | G5: 4.25 | H5: =-模型假设!$B$16 | I5: =-模型假设!$C$16 | J5: =-模型假设!$D$16 | K5: =-模型假设!$E$16 | L5: =-模型假设!$F$16
A6: 自由现金流（FCFF） | B6: 3.77 | C6: 4.6 | D6: 5.25 | E6: 6.05 | F6: 5.29 | G6: 6.4 | H6: =H4+H5 | I6: =I4+I5 | J6: =J4+J5 | K6: =K4+K5 | L6: =L4+L5
A7: 投资活动现金流
A8: 投资活动现金流 | B8: -1.5 | C8: -1.8 | D8: -2.1 | E8: -2.4 | F8: -2.85 | G8: -3.15 | H8: =-模型假设!$B$16*0.9 | I8: =-模型假设!$C$16*0.9 | J8: =-模型假设!$D$16*0.9 | K8: =-模型假设!$E$16*0.9 | L8: =-模型假设!$F$16*0.9
A9: 筹资活动现金流 | B9: -0.21 | C9: -0.32 | D9: -0.45 | E9: -0.58 | F9: -0.72 | G9: -0.85 | H9: =-利润表!H22*模型假设!$B$22 | I9: =-利润表!I22*模型假设!$C$22 | J9: =-利润表!J22*模型假设!$D$22 | K9: =-利润表!K22*模型假设!$E$22 | L9: =-利润表!L22*模型假设!$F$22
A11: 净现金增量 | B11: 0.11 | C11: 0.03 | D11: -0.1 | E11: -0.13 | F11: -2.13 | G11: -1.85 | H11: =H4+H8+H9 | I11: =I4+I8+I9 | J11: =J4+J8+J9 | K11: =K4+K8+K9 | L11: =L4+L8+L9
A12: 期初货币资金 | C12: 5.82 | D12: 7.45 | E12: 8.92 | F12: 9.85 | G12: 10.52 | H12: =G13 | I12: =H13 | J12: =I13 | K12: =J13 | L12: =K13
A13: 期末货币资金 | B13: 5.82 | C13: 7.45 | D13: 8.92 | E13: 9.85 | F13: 10.52 | G13: 12.15 | H13: =H12+H11 | I13: =I12+I11 | J13: =J12+J11 | K13: =K12+K11 | L13: =L12+L11

Sheet 利润表_季度
A1: 【利润表_季度】航宇科技（688239.SH）
A2: E=季节性预测 | 历史=已披露实际数据
A3: 科目 | B3: 2024Q1 | C3: 2024Q2 | D3: 2024Q3 | E3: 2024Q4 | F3: 2025Q1 | G3: 2025Q2 | H3: 2025Q3 | I3: 2025Q4 | J3: 2026Q1E | K3: 2026Q2E | L3: 2026Q3E | M3: 2026Q4E
A4: 营业收入 | B4: 5.78 | C4: 4.92 | D4: 4.12 | E4: 3.93 | F4: 4.22 | G4: 4.92 | H4: 6.1 | I4: 5.1 | J4: 5.8046402 | K4: 5.6591049 | L4: 5.8097217 | M4: 5.1531259
A5: YoY增速
A6: QoQ增速
A7: 营业成本 | B7: -4.1905 | C7: -3.55224 | D7: -2.95816 | E7: -2.80995 | F7: -3.07216 | G7: -3.55224 | H7: -4.3615 | I7: -3.6567 | J7: -4.179341 | K7: -4.0745555 | L7: -4.1829996 | M7: -3.7102507
A8: 毛利润 | B8: 1.5895 | C8: 1.36776 | D8: 1.16184 | E8: 1.12005 | F8: 1.14784 | G8: 1.36776 | H8: 1.7385 | I8: 1.4433 | J8: 1.6252993 | K8: 1.5845494 | L8: 1.6267221 | M8: 1.4428753
A9: 毛利率 | B9: 0.275 | C9: 0.278 | D9: 0.282 | E9: 0.285 | F9: 0.272 | G9: 0.278 | H9: 0.285 | I9: 0.283 | J9: 0.28 | K9: 0.28 | L9: 0.28 | M9: 0.28
A10: 销售费用 | B10: -0.1445 | C10: -0.123 | D10: -0.103 | E10: -0.09825 | F10: -0.1055 | G10: -0.123 | H10: -0.1525 | I10: -0.1275 | J10: -0.14511601 | K10: -0.14147762 | L10: -0.14524304 | M10: -0.12882815
A11: 管理费用 | B11: -0.3757 | C11: -0.3198 | D11: -0.2678 | E11: -0.25545 | F11: -0.2743 | G11: -0.3198 | H11: -0.3965 | I11: -0.3315 | J11: -0.37730161 | K11: -0.36784182 | L11: -0.37763191 | M11: -0.33495319
A12: 研发费用 | B12: -0.3468 | C12: -0.2952 | D12: -0.2472 | E12: -0.2358 | F12: -0.2532 | G12: -0.2952 | H12: -0.366 | I12: -0.306 | J12: -0.35988769 | K12: -0.3508645 | L12: -0.36020275 | M12: -0.31949381
A13: 财务费用 | B13: -0.0289 | C13: -0.0246 | D13: -0.0206 | E13: -0.01965 | F13: -0.0211 | G13: -0.0246 | H13: -0.0305 | I13: -0.0255 | J13: -0.029023201 | K13: -0.028295525 | L13: -0.029048609 | M13: -0.02576563
A15: 营业利润 | B15: 0.92191 | C15: 0.7933008 | D15: 0.6738672 | E15: 0.649629 | F15: 0.6657472 | G15: 0.7933008 | H15: 1.00833 | I15: 0.837114 | J15: 0.94267357 | K15: 0.91903864 | L15: 0.94349881 | M15: 0.83686765
A17: 净利润（合并） | B17: 0.588 | C17: 1.092 | D17: 1.5435 | E17: 0.4725 | F17: 0.4515 | G17: 0.5775 | H17: 0.924 | I17: 0.546 | J17: 0.88375647 | K17: 0.86159872 | L17: 0.88453013 | M17: 0.78456343
A18: 归母净利润 | B18: 0.56 | C18: 1.04 | D18: 1.47 | E18: 0.45 | F18: 0.43 | G18: 0.55 | H18: 0.88 | I18: 0.52 | J18: 0.84167283 | K18: 0.82057021 | L18: 0.84240965 | M18: 0.74720326
A19: 归母净利YoY
A20: 归母净利QoQ
A21: EPS（元） | B21: 0.29473684 | C21: 0.54736842 | D21: 0.77368421 | E21: 0.23684211 | F21: 0.22631579 | G21: 0.28947368 | H21: 0.46315789 | I21: 0.27368421 | J21: 0.4429857 | K21: 0.43187906 | L21: 0.4433735 | M21: 0.39326487

Sheet 基本面研究
A1: 【基本面研究】航宇科技（688239.SH）
A2: 数据截至：2026-04-07
A4: ▌ 评分汇总
A5: 维度 | B5: 权重 | C5: 分值 | D5: 加权分
A6: A. 行业质量 | B6: 25% | C6: 3.8 | D6: =B6*C6
A7: B. 竞争壁垒 | B7: 25% | C7: 3.5 | D7: =B7*C7
A8: C. 增长能见度 | B8: 25% | C8: 3.5 | D8: =B8*C8
A9: D. 财务质量 | B9: 15% | C9: 3.2 | D9: =B9*C9
A10: E. 公司治理 | B10: 10% | C10: 3.5 | D10: =B10*C10
A11: ★ 综合质量得分 | D11: =SUM(D6:D10)
A13: ★ 投资质量等级
A14: > 3.8 = A档（优秀）| 3.0-3.8 = B档（良好）| < 3.0 = C档（一般）
A15: 综合得分：3.5 → B档（良好）
A17: ▌ A. 行业质量详细评分（权重25%）
A18: 子维度 | B18: 权重 | C18: 得分 | D18: 评分依据
A19: 行业规模（TAM） | B19: 5% | C19: 4 | D19: 中国航空航天核心产业规模突破2万亿元
A20: 行业增速（未来5年CAGR） | B20: 5% | C20: 4 | D20: 商业航天CAGR~20%，低空经济CAGR超20%
A21: 行业延展性 | B21: 5% | C21: 4 | D21: C919/ARJ21放量，商业航天/卫星互联网打开空间
A22: 行业透明度 | B22: 5% | C22: 3.5 | D22: 竞争格局有序，环形锻件CR3高
A23: 政策友好度 | B23: 5% | C23: 4 | D23: 国防预算+7.2%，军民融合政策持续推进
A26: ▌ B. 竞争壁垒详细评分（权重25%）
A27: 子维度 | B27: 权重 | C27: 得分 | D27: 评分依据
A28: 技术壁垒 | B28: 5% | C28: 4 | D28: NSP技术获全球航空龙头认证，节省原材料20-50%
A29: 定价权 | B29: 5% | C29: 3.5 | D29: 毛利率28%稳定，NSP推广有提升空间
A30: 垄断地位 | B30: 5% | C30: 4 | D30: 国内航空环形锻件龙头，全球三强之一
A31: 客户粘性 | B31: 5% | C31: 4 | D31: GE/赛峰/罗罗/普惠认证，客户转换成本极高
A32: 进入壁垒 | B32: 5% | C32: 3 | D32: 航空锻件资质认证3-5年，有一定壁垒
A33: 供应商议价 | B33: 5% | C33: 3 | D33: 高温合金供应商分散，议价能力中
A34: 客户集中度 | B34: 5% | C34: 3 | D34: 商发占比85-90%，集中度偏高
A35: 替代品威胁 | B35: 5% | C35: 3.5 | D35: 无明显替代品，技术替代风险低
A38: ▌ C. 增长能见度详细评分（权重25%）
A39: 子维度 | B39: 权重 | C39: 得分 | D39: 评分依据
A40: 在手订单充裕度 | B40: 8% | C40: 4.5 | D40: 在手订单60亿元，覆盖2026-2027年
A41: 产能爬坡 | B41: 7% | C41: 3.5 | D41: 贵阳70-80%，德阳新投产，匈牙利规划中
A42: 新需求开拓 | B42: 5% | C42: 4 | D42: 燃气轮机/核电/半导体设备打开新空间
A43: 生命周期 | B43: 5% | C43: 3 | D43: 成长期中段，国内交付节奏波动影响短期
A46: ▌ D. 财务质量详细评分（权重15%）
A47: 子维度 | B47: 权重 | C47: 得分 | D47: 评分依据
A48: CFO/净利润 | B48: 4% | C48: 3 | D48: 2024年经营现金流1.44亿/净利1.89亿=76%
A49: ROE趋势 | B49: 4% | C49: 3 | D49: ROE 9.87%属中等，2025年略降至9.76%
...

Sheet 估值分析
A1: 【估值分析】航宇科技（688239.SH）
A2: 报告日期：2026-04-07 | 当前股价：54.14元
A4: ▌ PE 估值法
B5: 2024A | C5: 2025A | D5: 2026E | E5: 2027E | F5: 2028E
A6: EPS（元） | B6: 1.3 | C6: 0.98 | D6: =利润表!H25 | E6: =利润表!I25 | F6: =利润表!J25
A7: PE倍数 | B7: 41.6 | C7: 55.2 | D7: 40 | E7: 35 | F7: 30
A8: 目标股价 | B8: 54.1 | C8: 54.1 | D8: =D6*D7 | E8: =E6*E7 | F8: =F6*F7
A10: ▌ PEGY 估值法
A11: FY1E EPS | D11: =D6
A12: FY1E PE（当前） | D12: 55.2
A13: 净利润增速（FY1） | D13: 0.715
A14: 股息率（TTM） | D14: 0.028
A15: PEG | D15: =D12/D13
A16: PEGY | D16: =D12/(D13+D14)
A17: 合理PEGY区间 | D17: 0.8-1.2x
A18: PEGY隐含目标价 | D18: =D6*(D13+D14)*1.0
A20: ▌ 估值汇总
A21: 方法 | B21: 目标价（元） | C21: 当前股价（元） | D21: 上行空间
A22: PE法（2026E 40x） | B22: 66.8 | C22: 54.14 | D22: =(B22-C22)/C22
A23: PE法（2027E 35x） | B23: 77.4 | C23: 54.14 | D23: =(B23-C23)/C23
A24: PE法（2028E 30x） | B24: 81.6 | C24: 54.14 | D24: =(B24-C24)/C24
A25: PEGY法 | B25: =D18 | C25: 54.14 | D25: =(B25-C25)/C25
A26: 分析师平均 | B26: 68 | C26: 54.14 | D26: =(B26-C26)/C26
A28: ★ 综合估值结论
A29: 目标价区间：64-72元（基于2026E PE 40-45x）
A30: 上行空间：+18%~+33%
A31: 投资评级：中性偏乐观（边际改善）
